Workbook

Sheet Summary_Store
A1: No. | B1: Category | C1: Qty | D1: Notes | E1: HCM | F1: South stores (other than HCM) | G1: HN | H1: North stores (other than HN)
A2: 1 | B2: Number of active stores | C2: =COUNTIFS(#REF!,"Open",#REF!,"Store") + COUNTIFS(#REF!,"Open",#REF!,"Multi PC") + COUNTIFS(#REF!,"Open",#REF!,"Mono") + COUNTIFS(#REF!,"Open",#REF!,"SIS") -> #REF! | E2: =COUNTIFS(#REF!,"Open",#REF!,"Store",#REF!,"Ho Chi Minh City") + COUNTIFS(#REF!,"Open",#REF!,"Mono",#REF!,"Ho Chi Minh City") + COUNTIFS(#REF!,"Open",#REF!,"SIS",#REF!,"Ho Chi Minh City") -> #REF! | F2: =(COUNTIFS(#REF!,"Open",#REF!,"Store",#REF!,"South") + COUNTIFS(#REF!,"Open",#REF!,"Mono",#REF!,"South") + COUNTIFS(#REF!,"Open",#REF!,"SIS",#REF!,"South"))-E2 -> #REF! | G2: =COUNTIFS(#REF!,"Open",#REF!,"Store",#REF!,"Ha Noi") + COUNTIFS(#REF!,"Open",#REF!,"Mono",#REF!,"Ha Noi") + COUNTIFS(#REF!,"Open",#REF!,"SIS",#REF!,"Ha Noi") -> #REF! | H2: =(COUNTIFS(#REF!,"Open",#REF!,"Store",#REF!,"North") + COUNTIFS(#REF!,"Open",#REF!,"Mono",#REF!,"North") + COUNTIFS(#REF!,"Open",#REF!,"SIS",#REF!,"North"))-G2 -> #REF!
A3: =A2+1 -> 2 | B3: Number of active bazaar | C3: =COUNTIFS(#REF!,"Open",#REF!,"Bazaar") -> #REF!
A4: =A3+1 -> 3 | B4: Number of active events, private sales | C4: {=SUM(COUNTIFS(#REF!,"Open",#REF!,{"EVENT","PRIVATE SALE"}))} -> #REF!
A5: =A4+1 -> 4 | B5: Total (active) | C5: =SUM(C2:C4) -> #REF!
A6: =A5+1 -> 5 | B6: Existing stores that need to deploy FG-40F | C6: =COUNTIFS(#REF!,"Open",#REF!,"Need to deploy (FG-40F)") -> #REF!
A7: =A6+1 -> 6 | B7: Existing stores that need to deploy FG-60F | C7: =COUNTIFS(#REF!,"Need to deploy (FG-60F)") -> #REF!
A8: =A7+1 -> 7 | B8: Extra Details - Number of active Mono stores | C8: =COUNTIFS(#REF!,"Open",#REF!,"Store") + COUNTIFS(#REF!,"Open",#REF!,"Mono") -> #REF!
A9: =A8+1 -> 8 | B9: Extra Details - Number of active SIS stores | C9: =COUNTIFS(#REF!,"Open",#REF!,"Store") + COUNTIFS(#REF!,"Open",#REF!,"SIS") -> #REF!
A10: =A9+1 -> 9 | B10: Stores enabled O2O | C10: =COUNTIFS(#REF!,"Open",#REF!,"Yes") -> #REF!

Sheet Asset_Office
A1: No. | B1: Asset ID | C1: Status (formula) | D1: Assigned To (formula) | E1: Description (formula) | F1: Hostname | G1: AD User (formula) | H1: Location | I1: Asset Name (formula) | J1: Asset Type (formula) | K1: Brand | L1: Model | M1: S/N | N1: RAM (GB) | O1: Hard Disk (GB) | P1: Hard Disk Type | Q1: CPU | R1: Purchase Date | S1: Vendor/Supplier | T1: Note | V1: Assignment History | W1: USB TOKEN | X1: Old Hostname | Y1: AD unjoin, change hostname | Z1: PASTE ASSET ID | AA1: Status BIGFIX | AB1: STATUS Crowdstrike | AC1: STATUS JOIN DOMAIN
A2: 1 | B2: 22VN00000001 | C2: In Use | D2: =VLOOKUP(B2,VN_Emails!B:H,4,0) -> Tiet Nha Phung | E2: =VLOOKUP(B2,VN_Emails!B:H,7,0) -> Brand Manager (Converse) | F2: AMMAVNAMC000001 | G2: =SUBSTITUTE(VLOOKUP(B2,VN_Emails!B:H,2,0),"@mapactive.vn","") -> phung.tietnha | H2: Office | I2: =J2&" "&K2&" "&L2 -> Laptop HP Latitude 7420 | J2: Laptop | K2: HP | L2: Latitude 7420 | M2: DVV62J3 | N2: 16 | O2: 512 | P2: SSD | Q2: 1700 MHz 11th Gen Intel Core i7-1165G7 @ 2.80GHz | X2: MMA-LAP-0001 | Y2: DONE | Z2: DONE | AA2: DONE | AB2: DONE | AC2: Created it.active local account
A3: =A2+1 -> 2 | B3: 22VN00000002 | C3: In Use | D3: =VLOOKUP(B3,VN_Emails!B:H,4,0) -> Doan Thien Ho An | E3: =VLOOKUP(B3,VN_Emails!B:H,7,0) -> Digital Marketing Manager | F3: AMMAVNACC000002 | G3: =SUBSTITUTE(VLOOKUP(B3,VN_Emails!B:H,2,0),"@mapactive.vn","") -> Doan.An | H3: Office | I3: =J3&" "&K3&" "&L3 -> Laptop Dell Latitude 7420 | J3: Laptop | K3: Dell | L3: Latitude 7420 | M3: 124N1J3 | N3: 16 | O3: 512 | P3: SSD | Q3: 1700 MHz 11th Gen Intel Core i7-1165G7 @ 2.80GHz | V3: DANG BH LAPTOP KO LÊN NGUỒN | X3: MMA-LAP-0002 | Y3: Need to do both | Z3: DONE | AA3: DONE | AB3: DONE
A4: =A3+1 -> 3 | B4: 22VN00000003 | C4: Available | D4: =VLOOKUP(B4,VN_Emails!B:H,4,0) -> #N/A | E4: =VLOOKUP(B4,VN_Emails!B:H,7,0) -> #N/A | F4: AMMAVNACC000003 | G4: =SUBSTITUTE(VLOOKUP(B4,VN_Emails!B:H,2,0),"@mapactive.vn","") -> #N/A | H4: Office | I4: =J4&" "&K4&" "&L4 -> Laptop Dell Latitude 5420 | J4: Laptop | K4: Dell | L4: Latitude 5420 | M4: 1Z8DZH3 | N4: 16 | O4: 512 | P4: SSD | Q4: 1400 MHz 11th Gen Intel Core i5-1135G7 @ 2.40GHz | T4: UPDATE NEW SSD 500GB SAMSUNG | V4: đã bh ssd vs CMCSG samsung 500GB lưu kho IT Lấy ổ cứng SSD đã bảo hành của chị Mai (M.2 SSD - Model A60 - 512GB - S/N: 23027592-050170B) để thay vào laptop Dell Latitude 7420 của chị Uyên Máy cũ chị Maya đã thu hồi 22/01/2024 , Hiếu IT đang giữ | W4: use USB token | X4: MMA-LAP-0003 | Y4: DONE | Z4: DONE | AA4: DONE | AB4: DONE
A5: =A4+1 -> 4 | B5: 22VN00000004 | C5: In Use | D5: =VLOOKUP(B5,VN_Emails!B:H,4,0) -> Nguyen Thi Thuy Mong | E5: =VLOOKUP(B5,VN_Emails!B:H,7,0) -> Senior Brand Marketing Manager | F5: AMMAVNACC000004 | G5: =SUBSTITUTE(VLOOKUP(B5,VN_Emails!B:H,2,0),"@mapactive.vn","") -> mong.nguyenthithuy | H5: Office | I5: =J5&" "&K5&" "&L5 -> Laptop Dell Latitude 5430 | J5: Laptop | K5: Dell | L5: Latitude 5430 | M5: 42X2SQ3 | N5: 8 | O5: 512 | P5: SSD | Q5: 2500 MHz 12th Gen Intel Core i5-1235U | V5: Máy của Danh thỉnh thoảng không lên màn hình | X5: MMA-LAP-0004 | Y5: DONE | Z5: DONE | AA5: DONE | AB5: DONE
A6: =A5+1 -> 5 | B6: 22VN00000006 | C6: In Use | D6: =VLOOKUP(B6,VN_Emails!B:H,4,0) -> Le Hong Bao Chau | E6: old laptop Nguyen Hoang Anh Thy Accounting | F6: AMMAVNACC000006 | H6: Office | I6: =J6&" "&K6&" "&L6 -> Laptop Dell Latitude 3520 | J6: Laptop | K6: Dell | L6: Latitude 3520 | M6: 5R4JGL3 | N6: 8 | O6: 256 | P6: SSD | Q6: 1400 MHz 11th Gen Intel Core i5-1135G7 @ 2.40GHz | V6: old laptop Nguyen Hoang Anh Thy Accounting, IT thu hồi 21-02-2024 | X6: AMMAVNACC000006 | Y6: DONE | Z6: DONE | AA6: DONE | AB6: DONE
A7: =A6+1 -> 6 | B7: 22VN00000007 | C7: In Use | D7: =VLOOKUP(B7,VN_Emails!B:H,4,0) -> Van Huynh Tu Trinh | E7: =VLOOKUP(B7,VN_Emails!B:H,7,0) -> Receivable Accountant | F7: AMMAVNACCC000007 | G7: =SUBSTITUTE(VLOOKUP(B7,VN_Emails!B:H,2,0),"@mapactive.vn","") -> trinh.vanhuynhtu | H7: Office | I7: =J7&" "&K7&" "&L7 -> Laptop Dell Latitude 3420 | J7: Laptop | K7: Dell | L7: Latitude 3420 | M7: 65G48S3 | N7: 16 | O7: 512 | P7: SSD | Q7: 1400 MHz 11th Gen Intel Core i5-1135G7 @ 2.40GHz | X7: MMA-LAP-0007 | Y7: DONE | Z7: DONE | AA7: DONE | AB7: DONE
A8: =A7+1 -> 7 | B8: 22VN00000008 | C8: Available | D8: =VLOOKUP(B8,VN_Emails!B:H,4,0) -> #N/A | E8: =VLOOKUP(B8,VN_Emails!B:H,7,0) -> #N/A | F8: AMMAVNACC000008 | G8: =SUBSTITUTE(VLOOKUP(B8,VN_Emails!B:H,2,0),"@mapactive.vn","") -> #N/A | H8: Office | I8: =J8&" "&K8&" "&L8 -> Laptop Dell Latitude 3520 | J8: Laptop | K8: Dell | L8: Latitude 3520 | M8: 2P8VKG3 | N8: 8 | O8: 512 | P8: SSD | Q8: 1400 MHz 11th Gen Intel Core i3-1135G7 @ 2.40GHz | W8: use USB token | X8: MMA-LAP-0008 | Y8: DONE | Z8: DONE | AA8: DONE | AB8: DONE
A9: =A8+1 -> 8 | B9: 22VN00000009 | C9: In Use | D9: =VLOOKUP(B9,VN_Emails!B:H,4,0) -> Le Cam Linh | E9: =VLOOKUP(B9,VN_Emails!B:H,7,0) -> Shipping Supervisor | F9: AMMAVNLOC000009 | G9: =SUBSTITUTE(VLOOKUP(B9,VN_Emails!B:H,2,0),"@mapactive.vn","") -> linh.lecam | H9: Office | I9: =J9&" "&K9&" "&L9 -> Laptop Dell Latitude 5430 | J9: Laptop | K9: Dell | L9: Latitude 5430 | M9: 1583SQ3 | N9: 20 | O9: 512 | P9: SSD | Q9: 2500 MHz 12th Gen Intel Core i5-1235U | X9: MMA-LAP-0009 | Y9: DONE | AA9: DONE | AB9: DONE
A10: =A9+1 -> 9 | B10: 22VN00000010 | C10: In Use | D10: =VLOOKUP(B10,VN_Emails!B:H,4,0) -> Vo Ngoc Thanh Ngan | E10: =VLOOKUP(B10,VN_Emails!B:H,7,0) -> Intern | F10: AMMAVNROC000010 | G10: =SUBSTITUTE(VLOOKUP(B10,VN_Emails!B:H,2,0),"@mapactive.vn","") -> ngan.vongocthanh | H10: Office | I10: =J10&" "&K10&" "&L10 -> Laptop Dell Latitude 3520 | J10: Laptop | K10: Dell | L10: Latitude 3520 | M10: 4Q9VKG3 | N10: 8 | O10: 256 | P10: SSD | Q10: 2200 MHz 11th Gen Intel Core i3-1115G4 @ 3.00GHz | V10: Máy Mỹ TRang cũ | X10: MMA-LAP-0010 | Y10: DONE | Z10: DONE | AA10: DONE | AB10: DONE
A11: =A10+1 -> 10 | B11: 22VN00000011 | C11: In Use | D11: =VLOOKUP(B11,VN_Emails!B:H,4,0) -> Nguyen Bao Ngoc | E11: =VLOOKUP(B11,VN_Emails!B:H,7,0) -> Division Operation Manager | F11: AMMAVNMDC000011 | G11: =SUBSTITUTE(VLOOKUP(B11,VN_Emails!B:H,2,0),"@mapactive.vn","") -> Ngoc.nguyenbao | H11: Office | I11: =J11&" "&K11&" "&L11 -> Laptop Dell Latitude 5430 | J11: Laptop | K11: Dell | L11: Latitude 5430 | M11: F083SQ3 | N11: 8 | O11: 512 | P11: SSD | Q11: 2500 MHz 12th Gen Intel Core i5-1235U | V11: SỬ DỤNG MÁY 5430 CỦA LƯU GIANG CẨM VÂN(VICKY) ĐÃ THAY SSD BỊ HƯ TỪ CMC (LẦN 1) CHỜ CỨU DATA TỪ SÓNG NAM SAU ĐÓ BH SSD VS CMC(SAU TẾT) CMC ĐÃ GỬI LẠI SSD MỚI NGÀY 08/03/2024 | X11: MMA-LAP-0011 | Y11: DONE | Z11: DONE | AA11: DONE | AB11: DONE
A12: =A11+1 -> 11 | B12: 22VN00000012 | C12: Available | D12: =VLOOKUP(B12,VN_Emails!B:H,4,0) -> #N/A | E12: =VLOOKUP(B12,VN_Emails!B:H,7,0) -> #N/A | F12: AMMAVNHRC000012 | G12: =SUBSTITUTE(VLOOKUP(B12,VN_Emails!B:H,2,0),"@mapactive.vn","") -> #N/A | H12: Office | I12: =J12&" "&K12&" "&L12 -> Laptop Dell Latitude 3520 | J12: Laptop | K12: Dell | L12: Latitude 3520 | M12: BR9VKG3 | N12: 8 | O12: 256 | P12: SSD | Q12: 2200 MHz 11th Gen Intel Core i3-1115G4 @ 3.00GHz | T12: Máy lỗi loa user binh.ngotieu 16/05/24, Cấp tạm cho Lan Vy Cấp ZV16 26/08/2024 | X12: MMA-LAP-0012 | Y12: DONE | Z12: DONE | AA12: DONE | AB12: DONE
A13: =A12+1 -> 12 | B13: 22VN00000013 | C13: In Use | D13: =VLOOKUP(B13,VN_Emails!B:H,4,0) -> Tran Thi Yen Nhi | E13: =VLOOKUP(B13,VN_Emails!B:H,7,0) -> Payroll & Em. Servieces Executive | F13: AMMAVNHRC000013 | G13: =SUBSTITUTE(VLOOKUP(B13,VN_Emails!B:H,2,0),"@mapactive.vn","") -> nhi.tranthiyen | H13: Office | I13: =J13&" "&K13&" "&L13 -> Laptop HP Pavilion 15-eg0xxx | J13: Laptop | K13: HP | L13: Pavilion 15-eg0xxx | M13: 5CD1294NHX | N13: 8 | O13: 512 | P13: SSD | Q13: 2400 MHz 11th Gen Intel Core i5-1135G7 @ 2.40GHz | W13: use USB token | X13: MMA-LAP-0013 | Y13: DONE | Z13: DONE | AA13: DONE | AB13: DONE
A14: =A13+1 -> 13 | B14: 22VN00000014 | C14: In Use | D14: =VLOOKUP(B14,VN_Emails!B:H,4,0) -> Ni Ksormahhko | E14: =VLOOKUP(B14,VN_Emails!B:H,7,0) -> Procurement Executive | F14: AMMAVNPUC000014 | G14: =SUBSTITUTE(VLOOKUP(B14,VN_Emails!B:H,2,0),"@mapactive.vn","") -> ni.ksormahhko | H14: Office | I14: =J14&" "&K14&" "&L14 -> Laptop Dell Latitude 3520 | J14: Laptop | K14: Dell | L14: Latitude 3520 | M14: BKY5FX3 | N14: 8 | O14: 256 | P14: SSD | Q14: 11TH Gen Intel ® Core™ i5-1135G7 @2.40Ghz | X14: MMA-LAP-0014 | Y14: DONE | Z14: DONE | AA14: DONE | AB14: DONE
A15: =A14+1 -> 14 | B15: 22VN00000015 | C15: In Use | D15: =VLOOKUP(B15,VN_Emails!B:H,4,0) -> Huynh Tuan Nhan | E15: =VLOOKUP(B15,VN_Emails!B:H,7,0) -> SCM Manager | F15: AMMAVNLOC000015 | G15: =SUBSTITUTE(VLOOKUP(B15,VN_Emails!B:H,2,0),"@mapactive.vn","") -> nhan.huynhtuan | H15: Office | I15: =J15&" "&K15&" "&L15 -> Laptop Dell Latitude 5430 | J15: Laptop | K15: Dell | L15: Latitude 5430 | M15: 13D4SQ3 | N15: 16 | O15: 512 | P15: SSD | Q15: 2500 MHz 12th Gen Intel Core i5-1235U | X15: MMA-LAP-0015 | Y15: DONE | Z15: DONE | AA15: DONE | AB15: DONE
A16: =A15+1 -> 15 | B16: 22VN00000016 | C16: Available | D16: =VLOOKUP(B16,VN_Emails!B:H,4,0) -> #N/A | E16: =VLOOKUP(B16,VN_Emails!B:H,7,0) -> #N/A | F16: AMMAVNLOC000016 | G16: =SUBSTITUTE(VLOOKUP(B16,VN_Emails!B:H,2,0),"@mapactive.vn","") -> #N/A | H16: Office | I16: =J16&" "&K16&" "&L16 -> Laptop Dell Latitude 3520 | J16: Laptop | K16: Dell | L16: Latitude 3520 | M16: 99C2LG3 | N16: 12 | O16: 512 | P16: SSD | Q16: 2200 MHz 11th Gen Intel Core i3-1115G4 @ 3.00GHz | T16: Nâng 4gb Ram và 256GB SSD | X16: MMA-LAP-0016 | Y16: DONE | Z16: DONE | AA16: DONE | AB16: DONE
A17: =A16+1 -> 16 | B17: 22VN00000017 | C17: Available | D17: =VLOOKUP(B17,VN_Emails!B:H,4,0) -> #N/A | E17: =VLOOKUP(B17,VN_Emails!B:H,7,0) -> #N/A | F17: AMMAVNWHC000017 | G17: =SUBSTITUTE(VLOOKUP(B17,VN_Emails!B:H,2,0),"@mapactive.vn","") -> #N/A | H17: Office | I17: =J17&" "&K17&" "&L17 -> Laptop Dell Latitude 3520 | J17: Laptop | K17: Dell | L17: Latitude 3520 | M17: JP8VKG3 | N17: 16 | O17: 256 | P17: SSD | Q17: 2200 MHz 11th Gen Intel Core i3-1115G4 @ 3.00GHz | X17: MMA-LAP-0017 | Y17: DONE | Z17: DONE | AA17: DONE | AB17: DONE
A18: =A17+1 -> 17 | B18: 22VN00000018 | C18: In Use | D18: =VLOOKUP(B18,VN_Emails!B:H,4,0) -> Dang Thanh Nam | E18: =VLOOKUP(B18,VN_Emails!B:H,7,0) -> Warehouse and Distribution Supervisor | F18: AMMAVNWHC000018 | G18: =SUBSTITUTE(VLOOKUP(B18,VN_Emails!B:H,2,0),"@mapactive.vn","") -> nam.dangthanh | H18: Office | I18: =J18&" "&K18&" "&L18 -> Laptop Dell Latitude 3520 | J18: Laptop | K18: Dell | L18: Latitude 3520 | M18: JR9VKG3 | N18: 8 | O18: 256 | P18: SSD | Q18: 2200 MHz 11th Gen Intel Core i3-1115G4 @ 3.00GHz | X18: MMA-LAP-0018 | Y18: DONE | Z18: DONE | AA18: DONE | AB18: DONE
A19: =A18+1 -> 18 | B19: 22VN00000019 | C19: Available | E19: =VLOOKUP(B19,VN_Emails!B:H,7,0) -> #N/A | F19: AMMAVNLOC000019 | G19: =SUBSTITUTE(VLOOKUP(B19,VN_Emails!B:H,2,0),"@mapactive.vn","") -> #N/A | H19: Office | I19: =J19&" "&K19&" "&L19 -> Laptop Dell Latitude 3520 | J19: Laptop | K19: Dell | L19: Latitude 3520 | M19: FQ8VKG3 | N19: 8 | O19: 256 | P19: SSD | Q19: 2200 MHz 11th Gen Intel Core i3-1115G4 @ 3.00GHz | X19: MMA-LAP-0019 | Y19: DONE | Z19: DONE | AA19: DONE | AB19: DONE
A20: =A19+1 -> 19 | B20: 22VN00000020 | C20: In Use | D20: Quan Thanh Them | E20: =VLOOKUP(B20,VN_Emails!B:H,7,0) -> COE Manager | F20: AMMAVNCEC000020 | G20: =SUBSTITUTE(VLOOKUP(B20,VN_Emails!B:H,2,0),"@mapactive.vn","") -> them.quanthanh | H20: Office | I20: =J20&" "&K20&" "&L20 -> Laptop Dell Latitude 5430 | J20: Laptop | K20: Dell | L20: Latitude 5430 | M20: 5BD4SQ3 | N20: 16 | O20: 512 | P20: SSD | Q20: 2500 MHz 12th Gen Intel Core i5-1235U | X20: MMA-LAP-0020 | Y20: DONE | Z20: DONE | AA20: DONE | AB20: DONE
A21: =A20+1 -> 20 | B21: 22VN00000021 | C21: In Use | D21: =VLOOKUP(B21,VN_Emails!B:H,4,0) -> Nguyen Ngoc Xuan Duyen | E21: =VLOOKUP(B21,VN_Emails!B:H,7,0) -> COE Officer | F21: AMMAVNCEC000021 | G21: =SUBSTITUTE(VLOOKUP(B21,VN_Emails!B:H,2,0),"@mapactive.vn","") -> duyen.nguyenngocxuan | H21: Office | I21: =J21&" "&K21&" "&L21 -> Laptop Dell Latitude 3520 | J21: Laptop | K21: Dell | L21: Latitude 3520 | M21: BTN0BG3 | N21: 8 | O21: 256 | P21: SSD | Q21: 2200 MHz 11th Gen Intel Core i3-1115G4 @ 3.00GHz | X21: MMA-LAP-0021 | Y21: DONE | Z21: DONE | AA21: DONE | AB21: DONE
A22: =A21+1 -> 21 | B22: 22VN00000022 | C22: In Use | D22: =VLOOKUP(B22,VN_Emails!B:H,4,0) -> Nguyen Quyet Thang | E22: =VLOOKUP(B22,VN_Emails!B:H,7,0) -> COE Officer | F22: AMMAVNCEC000022 | G22: thang.nguyenquyet | H22: Office | I22: =J22&" "&K22&" "&L22 -> Laptop Dell Latitude 3520 | J22: Laptop | K22: Dell | L22: Latitude 3520 | M22: DP8VKG3 | N22: 8 | O22: 256 | P22: SSD | Q22: 2200 MHz 11th Gen Intel Core i3-1115G4 @ 3.00GHz | V22: LE MINH KHANG OLD LAPTOP (COE Officer) resigned 29-01-2024 - 25/03/2024 handover for Tạ Quỳnh Trang -16/07/2024 handover for Trần Hồ Duy Tân | X22: MMA-LAP-0022 | Y22: DONE | Z22: DONE | AA22: DONE | AB22: DONE
A23: =A22+1 -> 22 | B23: 22VN00000023 | C23: In Use | D23: =VLOOKUP(B23,VN_Emails!B:H,4,0) -> Nguyen Bao Du | E23: IT BACKUP | F23: AMMAVNCEC000023 | H23: Office | I23: =J23&" "&K23&" "&L23 -> Laptop Dell Latitude 3520 | J23: Laptop | K23: Dell | L23: Latitude 3520 | M23: 6S4JGL3 | N23: 8 | O23: 256 | P23: SSD | Q23: 1400 MHz 11th Gen Intel Core i5-1135G7 @ 2.40GHz | V23: - Tran Dang Anh Khoa (COE Officer) resigned - Cấp tạm cho DƯƠNG QUANG MINH TUẤN THAY cho HỒ HẢI ĐĂNG AM IT ĐÃ THU HỒI 30-01-24 | W23: DISABLE | X23: MMA-LAP-0023 | Y23: DONE | Z23: DONE | AA23: DONE | AB23: DONE | AC23: DONE
A24: =A23+1 -> 23 | B24: 22VN00000024 | C24: Available | D24: =VLOOKUP(B24,VN_Emails!B:H,4,0) -> #N/A | E24: =VLOOKUP(B24,VN_Emails!B:H,7,0) -> #N/A | F24: AMMAVNICC000024 | G24: =SUBSTITUTE(VLOOKUP(B24,VN_Emails!B:H,2,0),"@mapactive.vn","") -> #N/A | H24: Office | I24: =J24&" "&K24&" "&L24 -> Laptop Dell Latitude 3520 | J24: Laptop | K24: Dell | L24: Latitude 3520 | M24: 4R9VKG3 | N24: 8 | O24: 256 | P24: SSD | Q24: 2200 MHz 11th Gen Intel Core i3-1115G4 @ 3.00GHz | X24: MMA-LAP-0024 | Y24: DONE | Z24: DONE | AA24: DONE | AB24: DONE
A25: =A24+1 -> 24 | B25: 22VN00000025 | C25: In Use | D25: =VLOOKUP(B25,VN_Emails!B:H,4,0) -> Luong Huu Quan | E25: =VLOOKUP(B25,VN_Emails!B:H,7,0) -> IT Infrastructure & Operations Supervisor | F25: AMMAVNITC000025 | G25: =SUBSTITUTE(VLOOKUP(B25,VN_Emails!B:H,2,0),"@mapactive.vn","") -> quan.luonghuu | H25: Office | I25: =J25&" "&K25&" "&L25 -> Laptop Dell Latitude 5430 | J25: Laptop | K25: Dell | L25: Latitude 5430 | M25: FGF3SQ3 | N25: 16 | O25: 512 | P25: SSD | Q25: 2500 MHz 12th Gen Intel Core i5-1235U | X25: MMA-LAP-0025 | Y25: DONE | Z25: DONE | AA25: DONE | AB25: DONE
A26: =A25+1 -> 25 | B26: 22VN00000026 | C26: Available | D26: IT BACKUP | E26: IT BACKUP | F26: AMMAVNITC000026 | H26: Office | I26: =J26&" "&K26&" "&L26 -> Laptop HP ProBook 440 G4 | J26: Laptop | K26: HP | L26: ProBook 440 G4 | M26: 5CD73626Y5 | N26: 16 | O26: 256 | P26: SSD | Q26: 2700 MHz Core i5-7200U | T26: anh.nguyenphamduy resigned 20/05/2024 | V26: -Dat.tranquoc (IT Officer) resigned 11/3/2024 | X26: MMA-LAP-0026 | Y26: DONE | Z26: DONE | AA26: DONE | AB26: DONE | AC26: DONE
A27: =A26+1 -> 26 | B27: 22VN00000027 | C27: In Use | D27: =VLOOKUP(B27,VN_Emails!B:H,4,0) -> Huynh My Danh | E27: =VLOOKUP(B27,VN_Emails!B:H,7,0) -> FP&A Supervisor | F27: AMMAVNMRC000027 | G27: =SUBSTITUTE(VLOOKUP(B27,VN_Emails!B:H,2,0),"@mapactive.vn","") -> danh.huynhmy | H27: Office | I27: =J27&" "&K27&" "&L27 -> Laptop Dell Latitude 5420 | J27: Laptop | K27: Dell | L27: Latitude 5420 | M27: HRQCZH3 | N27: 8 | O27: 512 | P27: SSD | Q27: 1400 MHz 11th Gen Intel Core i5-1135G7 @ 2.40GHz | X27: MMA-LAP-0027 | Y27: DONE | Z27: DONE | AA27: DONE | AB27: DONE
A28: =A27+1 -> 27 | B28: 22VN00000028 | C28: In Use | D28: =VLOOKUP(B28,VN_Emails!B:H,4,0) -> Nghiem Thi Hong Van | E28: =VLOOKUP(B28,VN_Emails!B:H,7,0) -> Senior Merchandise | F28: AMMAVNMDCC000028 | G28: =SUBSTITUTE(VLOOKUP(B28,VN_Emails!B:H,2,0),"@mapactive.vn","") -> van.nghiemthihong | H28: Office | I28: =J28&" "&K28&" "&L28 -> Laptop Dell Latitude 3520 | J28: Laptop | K28: Dell | L28: Latitude 3520 | M28: GN8VKG3 | N28: 12 | O28: 256 | P28: SSD | Q28: 2200 MHz 11th Gen Intel Core i3-1115G4 @ 3.00GHz | T28: BÀN GIAO CHO Nghiêm Thị Hồng Vân – Senior Merchandise – Brand Department – On board 15/10/2023 (nâng 4gb Ram) | V28: MÁY CŨ LÊ TRẦN THIÊN MINH | X28: MMA-LAP-0028 | Y28: DONE | Z28: DONE | AA28: DONE | AB28: DONE
A29: =A28+1 -> 28 | B29: 22VN00000029 | C29: Available | D29: =VLOOKUP(B29,VN_Emails!B:H,4,0) -> #N/A | E29: =VLOOKUP(B29,VN_Emails!B:H,7,0) -> #N/A | F29: AMMAVNITC000029 | G29: =SUBSTITUTE(VLOOKUP(B29,VN_Emails!B:H,2,0),"@mapactive.vn","") -> #N/A | H29: Office | I29: =J29&" "&K29&" "&L29 -> Laptop Dell Latitude 3520 | J29: Laptop | K29: Dell | L29: Latitude 3520 | M29: 1P8VKG3 | N29: 8 | O29: 256 | P29: SSD | Q29: 2200 MHz 11th Gen Intel Core i3-1115G4 @ 3.00GHz | T29: Máy cũ Minh (sracecrow) | V29: Pham Thi Bao Tram (MKT) handover Feb-29-2024 Old hostname: AMMAVNMRC000029 | X29: MMA-LAP-0029 | Y29: DONE | Z29: DONE | AA29: DONE | AB29: DONE
A30: =A29+1 -> 29 | B30: 22VN00000030 | C30: Available | E30: Huynh Thi Bich Ngan resigned NGuyenThao My resigned 13/11/2024 | F30: AMMAVNMRC000030 | G30: =SUBSTITUTE(VLOOKUP(B30,VN_Emails!B:H,2,0),"@mapactive.vn","") -> #N/A | H30: Office | I30: =J30&" "&K30&" "&L30 -> Laptop Lenovo Thinkpad X280 | J30: Laptop | K30: Lenovo | L30: Thinkpad X280 | M30: PC133K78 | N30: 8 | O30: 256 | P30: SSD | Q30: 1800 MHz Core i5-8250U | T30: - Replaced keyboard on 20-Aug-2023 cấp cho :Nguyen Thao My 27/11/2023 (replace Phan Thi Thuy Tien) | V30: - Phan Thị Thủy Tiên đã thôi việc ngày 06/10/23 - Huỳnh Thị Bích Ngân – thôi việc ngày 13/10/2023 | X30: MMA-LAP-0030 | Y30: DONE | Z30: DONE | AA30: DONE | AB30: DONE | AC30: DONE
A31: =A30+1 -> 30 | B31: 22VN00000031 | C31: Available | D31: =VLOOKUP(B31,VN_Emails!B:H,4,0) -> #N/A | E31: =VLOOKUP(B31,VN_Emails!B:H,7,0) -> #N/A | F31: AMMAVNMDC000031 | G31: =SUBSTITUTE(VLOOKUP(B31,VN_Emails!B:H,2,0),"@mapactive.vn","") -> #N/A | H31: Office | I31: =J31&" "&K31&" "&L31 -> Laptop Dell Latitude 5420 | J31: Laptop | K31: Dell | L31: Latitude 5420 | M31: 4DBCZH3 | N31: 8 | O31: 512 | P31: SSD\ | Q31: 1400 MHz 11th Gen Intel Core i5-1135G7 @ 2.40GHz | X31: MMA-LAP-0031 | Y31: DONE | Z31: DONE | AA31: DONE | AB31: DONE
A32: =A31+1 -> 31 | B32: 22VN00000032 | C32: In Use | D32: =VLOOKUP(B32,VN_Emails!B:H,4,0) -> Vu Xuan Uyen | E32: =VLOOKUP(B32,VN_Emails!B:H,7,0) -> Marketing officer | F32: AMMAVNLEC000032 | G32: =SUBSTITUTE(VLOOKUP(B32,VN_Emails!B:H,2,0),"@mapactive.vn","") -> uyen.vuxuan | H32: Office | I32: =J32&" "&K32&" "&L32 -> Laptop Dell Latitude 3420 | J32: Laptop | K32: Dell | L32: Latitude 3420 | M32: 6GV7R93 | N32: 8 | O32: 640 | P32: HDD (512 GB) SSD (128 GB) | Q32: 1400 MHz 11th Gen Intel Core i5-1135G7 @ 2.40GHz | T32: Quỳnh MD Bàn giao trả máy ngày 24/08/2023 > Chuyển sang cho Le Thi Kim Hồng (Legal) sử dụng ngày 11/09/2023 | W32: use USB token | X32: MMA-LAP-0032 | Y32: DONE | Z32: DONE | AA32: DONE | AB32: DONE
A33: =A32+1 -> 32 | B33: 22VN00000033 | C33: Available | D33: =VLOOKUP(B33,VN_Emails!B:H,4,0) -> #N/A | E33: =VLOOKUP(B33,VN_Emails!B:H,7,0) -> #N/A | F33: AMMAVNMDC000033 | G33: =SUBSTITUTE(VLOOKUP(B33,VN_Emails!B:H,2,0),"@mapactive.vn","") -> #N/A | H33: Office | I33: =J33&" "&K33&" "&L33 -> Laptop Dell Latitude 3520 | J33: Laptop | K33: Dell | L33: Latitude 3520 | M33: 9P8VKG3 | N33: 8 | O33: 256 | P33: SSD | Q33: 2200 MHz 11th Gen Intel Core i3-1115G4 @ 3.00GHz | X33: MMA-LAP-0033 | Y33: DONE | Z33: DONE | AA33: DONE | AB33: DONE
A34: =A33+1 -> 33 | B34: 22VN00000034 | C34: In Use | D34: =VLOOKUP(B34,VN_Emails!B:H,4,0) -> Tran A giang | E34: =VLOOKUP(B34,VN_Emails!B:H,7,0) -> Intern | F34: AMMAVNMDC000034 | G34: =SUBSTITUTE(VLOOKUP(B34,VN_Emails!B:H,2,0),"@mapactive.vn","") -> giang.trana | H34: Office | I34: =J34&" "&K34&" "&L34 -> Laptop Dell Latitude 3520 | J34: Laptop | K34: Dell | L34: Latitude 3520 | M34: DGBJGL3 | N34: 8 | O34: 256 | P34: SSD | Q34: 1400 MHz 11th Gen Intel Core i5-1135G7 @ 2.40GHz | X34: MMA-LAP-0034 | Y34: DONE | Z34: DONE | AA34: DONE | AB34: DONE
A35: =A34+1 -> 34 | B35: 22VN00000035 | C35: In Use | D35: =VLOOKUP(B35,VN_Emails!B:H,4,0) -> Dang Thi Thanh Tam | E35: =VLOOKUP(B35,VN_Emails!B:H,7,0) -> Brand Manager (NB, Crocs) | F35: AMMAVNMDC000035 | G35: =SUBSTITUTE(VLOOKUP(B35,VN_Emails!B:H,2,0),"@mapactive.vn","") -> tam.dangthithanh | H35: Office | I35: =J35&" "&K35&" "&L35 -> Laptop Dell Latitude 5420 | J35: Laptop | K35: Dell | L35: Latitude 5420 | M35: 4CBCZH3 | N35: 12 | O35: 512 | P35: SSD | Q35: 1400 MHz 11th Gen Intel Core i5-1135G7 @ 2.40GHz | X35: MMA-LAP-0035 | Y35: DONE | Z35: DONE | AA35: DONE | AB35: DONE
A36: =A35+1 -> 35 | B36: 22VN00000036 | C36: Reserved | D36: KN10 bán cho Maison | E36: Pham My Tu old laptop | F36: AMMAVNMDC000036 | H36: Office | I36: =J36&" "&K36&" "&L36 -> Laptop Lenovo Ideapad 5-15ITL05(82FG00M5VN) | J36: Laptop | K36: Lenovo | L36: Ideapad 5-15ITL05(82FG00M5VN) | M36: PF2Q30RQ | N36: 8 | O36: 512 | P36: SSD | Q36: 2400 MHz 11th Gen Intel Core i5-1135G7 @ 2.40GHz | T36: - Old laptop of Pham My Tu - Cần cài lại Windows | V36: - Old laptop of Pham My Tu | X36: MMA-LAP-0036 | Y36: DONE | Z36: DONE | AA36: DONE | AB36: DONE
A37: =A36+1 -> 36 | B37: 22VN00000037 | C37: In Use | D37: =VLOOKUP(B37,VN_Emails!B:H,4,0) -> Nguyen Phuoc Thanh | E37: =VLOOKUP(B37,VN_Emails!B:H,7,0) -> Merchandiser | F37: AMMAVNMDC000037 | G37: =SUBSTITUTE(VLOOKUP(B37,VN_Emails!B:H,2,0),"@mapactive.vn","") -> thanh.nguyenphuoc | H37: Office | I37: =J37&" "&K37&" "&L37 -> Laptop Dell Latitude 3520 | J37: Laptop | K37: Dell | L37: Latitude 3520 | M37: 6Q7JGL3 | N37: 12 | O37: 512 | P37: SSD | Q37: 1400 MHz 11th Gen Intel Core i5-1135G7 @ 2.40GHz | X37: MMA-LAP-0037 | Y37: DONE | Z37: DONE | AA37: DONE | AB37: DONE
A38: =A37+1 -> 37 | B38: 22VN00000038 | C38: In Use | D38: =VLOOKUP(B38,VN_Emails!B:H,4,0) -> Ngo Thi Bich Tram | E38: Ms. Jolie resigned (keep for replacement) | F38: AMMAVNMDC000038 | G38: =SUBSTITUTE(VLOOKUP(B38,VN_Emails!B:H,2,0),"@mapactive.vn","") -> tram.ngothibich | H38: Office | I38: =J38&" "&K38&" "&L38 -> Laptop Dell Latitude 5430 | J38: Laptop | K38: Dell | L38: Latitude 5430 | M38: 4TS3SQ3 | N38: 16 | O38: 512 | P38: SSD | Q38: 2500 MHz 12th Gen Intel Core i5-1235U | V38: Máy của TRƯƠNG HỒNG HƯƠNG BÀN GIAO (HIếu IT giữ) | X38: MMA-LAP-0038 | Y38: DONE | Z38: DONE | AA38: DONE | AB38: DONE
A39: ost | B39: 22VN00000039 | C39: In Use | D39: =VLOOKUP(B39,VN_Emails!B:H,4,0) -> Le Ngoc Bich Tram | E39: =VLOOKUP(B39,VN_Emails!B:H,7,0) -> Marketing Supervisor (Foot Locker) | F39: AMMAVNIT000039 | G39: =SUBSTITUTE(VLOOKUP(B39,VN_Emails!B:H,2,0),"@mapactive.vn","") -> tram.lengocbich | H39: Office | I39: =J39&" "&K39&" "&L39 -> Laptop Dell Latitude 3520 | J39: Laptop | K39: Dell | L39: Latitude 3520 | M39: HGBJGL3 | N39: 20 | O39: 256+512 | P39: SSD | Q39: 1400 MHz 11th Gen Intel Core i5-1135G7 @ 2.40GHz | V39: linh.thainhat resigned 24/04/2024 | X39: MMA-LAP-0039 | Y39: DONE | Z39: DONE | AA39: DONE | AB39: DONE
A40: =#REF!+1 -> #REF! | B40: 22VN00000041 | C40: In Use | D40: =VLOOKUP(B40,VN_Emails!B:H,4,0) -> Nguyen Thi Tuyet Nhung | E40: Nguyen Thi Quynh Giang resigned | F40: AMMAVNBPC000041 | G40: minh.lengocbao | H40: Office | I40: =J40&" "&K40&" "&L40 -> Laptop Dell Latitude 5430 | J40: Laptop | K40: Dell | L40: Latitude 5430 | M40: GB23SQ3 | N40: 16 | O40: 512 | P40: SSD | Q40: 2500 MHz 12th Gen Intel Core i5-1235U | T40: User giang.nguyenthiquynh bàn giao ngày 18/08/2023 | V40: IT nhận máy bh ssd lỗi ngày 06/02/24(cmc)> BH SAU TẾT đã bh xong bàn giao user ngày 29/02/24 | W40: DISABLE | X40: MMA-LAP-0041 | Y40: DONE | Z40: DONE | AA40: DONE | AB40: DONE | AC40: DONE
...

Sheet Warehosue mail
B1: No | C1: Email Address | D1: Full Name | E1: Display Name | F1: Hostname
B2: 1 | C2: Geodis.cs1@mapactive.vn | D2: Geodis.cs1 | E2: Geodis cs1
B3: 2 | C3: Geodis.cs2@mapactive.vn | D3: Geodis.cs2 | E3: Geodis cs2
B4: 3 | C4: Geodis.cs3@mapactive.vn | D4: Geodis.cs3 | E4: Geodis cs3
B5: 4 | C5: Geodis.inbound1@mapactive.vn | D5: Geodis.inbound1 | E5: Geodis inbound1
B6: 5 | C6: Geodis.inbound2@mapactive.vn | D6: Geodis.inbound2 | E6: Geodis inbound2
B7: 6 | C7: Geodis.outobund1@mapactive.vn | D7: Geodis.outobund1 | E7: Geodis outbound1
B8: 7 | C8: Geodis.outbound2@mapactive.vn | D8: Geodis.outbound2 | E8: Geodis outbound2

Sheet VN_Emails
A1: No. | B1: Assigned Asset | C1: Email Address | D1: Full Name | E1: Display Name | F1: English Name | G1: Department | H1: JOB TITLE | I1: O365 license | J1: Country | K1: Type | L1: Onboarding Date | M1: Request email | N1: Purchasing Request | O1: Laptop model | P1: Laptop delivery | Q1: Handover to user | R1: Notes | S1: MAP Level
A2: 1 | B2: 22VN00000086 | C2: uyen.nguyenhaphuong@mapactive.vn | D2: Nguyễn Hà Phượng Uyên | E2: Nguyen Ha Phuong Uyen | F2: Dory | G2: BOD (Finance) | H2: General Manager & Finance Controller | I2: E3 | J2: VN | K2: Office | S2: Senior General Manager
A3: 2 | B3: 22VN00000001 | C3: phung.tietnha@mapactive.vn | D3: Tiết Nhã Phụng | E3: Tiet Nha Phung | H3: Brand Manager (Converse) | I3: E3 | J3: VN | K3: Office | S3: Senior Manager
A4: 3 | B4: 22VN00000035 | C4: tam.dangthithanh@mapactive.vn | D4: Đặng Thị Thanh Tâm | E4: Dang Thi Thanh Tam | F4: Tansy | H4: Brand Manager (NB, Crocs) | I4: E3 | J4: VN | K4: Office | S4: Senior Manager
A5: 4 | B5: 22VN00000097 | C5: van.luugiangcam@mapactive.vn | D5: Lưu Giang Cẩm Vân | E5: Luu Giang Cam Van | F5: Vicky | H5: HR & Admin Manager | I5: E3 | J5: VN | K5: Office | S5: Manager
A6: 5 | B6: 22VN00000020 | C6: them.quanthanh@mapactive.vn | D6: Quan Thanh Thềm | E6: Quan Thanh Them | H6: COE Manager | I6: E3 | J6: VN | K6: Office | S6: Manager
A7: 6 | B7: 22VN00000099 | C7: nghia.thoihuu@mapactive.vn | D7: Thới Hũu Nghĩa | E7: Thoi Huu Nghia | H7: Senior Project Manager | I7: E3 | J7: VN | K7: Office | S7: Senior Manager
A8: 7 | B8: 22VN00000103 | C8: tuyen.vothuyminh@mapactive.vn | D8: Võ Thụy Minh Tuyền | E8: Vo Thuy Minh Tuyen | H8: Senior Merchandise | I8: E3 | J8: VN | K8: Office | S8: Associate Manager
A9: 8 | B9: 22VN00000101 | C9: tu.phammy@mapactive.vn | D9: Phạm Mỹ Tú | E9: Pham My Tu | H9: Senior Merchandise | I9: E3 | J9: VN | K9: Office | S9: Associate Manager
A10: 9 | B10: 22VN00000037 | C10: thanh.nguyenphuoc@mapactive.vn | D10: Nguyễn Phước Thạnh | E10: Nguyen Phuoc Thanh | H10: Merchandiser | I10: E3 | J10: VN | K10: Office | S10: Senior Executive
A11: 10 | B11: 22VN00000009 | C11: linh.lecam@mapactive.vn | D11: Lê Cẩm Linh | E11: Le Cam Linh | H11: Shipping Supervisor | I11: E3 | J11: VN | K11: Office | S11: Senior Executive
A12: 11 | B12: 22VN00000038 | C12: tram.ngothibich@mapactive.vn | D12: Ngô Thị Bích Trâm | E12: Ngo Thi Bich Tram | H12: Shipping Officer | I12: E3 | J12: VN | K12: Office | S12: Senior Associate
A13: 12 | B13: 22VN00000076 | C13: tuyet.lethianh@mapactive.vn | D13: Lê Thị Ánh Tuyết | E13: Le Thi Anh Tuyet | H13: Tax & Accounting Assistant Manager | I13: E3 | J13: VN | K13: Office | S13: Senior Associate
A14: 13 | B14: 22VN00000054 | C14: tuan.ngoanh@mapactive.vn | D14: Ngô Anh Tuấn | E14: Ngo Anh Tuan | H14: Senior Wholesaler | I14: E3 | J14: VN | K14: Office | S14: Executive
A15: 14 | B15: 22VN00000102 | C15: thang.nguyennam@mapactive.vn | D15: Nguyễn Nam Thắng | E15: Nguyen Nam Thang | H15: Senior Wholesaler | I15: E3 | J15: VN | K15: Office | S15: Executive
A16: 15 | B16: 22VN00000018 | C16: nam.dangthanh@mapactive.vn | D16: Đặng Thành Nam | E16: Dang Thanh Nam | H16: Warehouse and Distribution Supervisor | I16: E3 | J16: VN | K16: Office | S16: Senior Executive
A17: 16 | B17: 22VN00000098 | C17: quynh.mainguyendiem@mapactive.vn | D17: Mai Nguyễn Diễm Quỳnh | E17: Mai Nguyen Diem Quynh | H17: Payable Accountant | I17: E3 | J17: VN | K17: Office | S17: Senior Associate
... A25: 24 | B25: 22VN00000066 | C25: tram.duongthibao@mapactive.vn | D25: Dương Thị Bảo Trâm | E25: Duong Thi Bao Tram | H25: Wholesale Admin | I25: E3 | J25: VN | K25: Office | S25: Associate
A26: 25 | B26: 22VN00000078 | C26: anh.nguyenngoclan@mapactive.vn | D26: Nguyễn Ngọc Lan Anh | E26: Nguyen Ngoc Lan Anh | F26: Sophie | H26: Graphic Designer | I26: E3 | J26: VN | K26: Office | S26: Senior Executive
A27: 26 | B27: 22VN00000044 | C27: trinh.tranngocdoan@mapactive.vn | D27: Trần Ngọc Đoan Trinh | E27: Tran Ngoc Doan Trinh | H27: Senior Merchandise | I27: E3 | J27: VN | K27: Office | S27: Senior Manager
A28: 27 | B28: 22VN00000061 | C28: linh.lengocmy@mapactive.vn | D28: Lê Ngoc Mỹ Linh | E28: Le Ngoc My Linh | H28: Senior Merchandise | I28: E3 | J28: VN | K28: Office | L28: 44958
A29: 28 | B29: 22VN00000013 | C29: nhi.tranthiyen@mapactive.vn | D29: Trần Thị Yến Nhi | E29: Tran Thi Yen Nhi | H29: Payroll & Em. Servieces Executive | I29: E3 | J29: VN | K29: Office | S29: Senior Associate
A30: 29 | B30: 22VN00000014 | C30: ni.ksormahhko@mapactive.vn | D30: Ksormahhko NI | E30: Ni Ksormahhko | H30: Procurement Executive | I30: E3 | J30: VN | K30: Office | S30: Senior Associate
A31: 30 | B31: 22VN00000065 | C31: lan.nguyenphuong@mapactive.vn | D31: Nguyễn Phương Lan | E31: Nguyen Phuong Lan | G31: Legal | H31: Legal Manager | I31: E3 | J31: VN | K31: Office | L31: 44991 | M31: Done | N31: Done | O31: 5430 | P31: Done | Q31: Done
A32: 31 | B32: 22VN00000106 | C32: syed.umairhassan@mapactive.vn | D32: Syed Umair Hassan | E32: Syed Umair Hassan | G32: BOD (Merchandise) | H32: GM Merchandise | I32: E3 | J32: VN | K32: Office | L32: 45005 | M32: Done | Q32: Done | R32: Using the HP Laptop of Birkenstock Diamond Plaza
A33: 32 | B33: 22VN00000025 | C33: quan.luonghuu@mapactive.vn | D33: Lương Hữu Quân | E33: Luong Huu Quan | G33: IT | H33: IT Infrastructure & Operations Supervisor | I33: E3 | J33: VN | K33: Office | L33: 45012 | M33: Done | N33: Done | O33: 3520 | P33: Done | Q33: Done
A34: 33 | B34: 22VN00000015 | C34: nhan.huynhtuan@mapactive.vn | D34: Huỳnh Tuấn Nhân | E34: Huynh Tuan Nhan | G34: SCM | H34: SCM Manager | I34: E3 | J34: VN | K34: Office | L34: 45019 | M34: Done | N34: No need | O34: No need | P34: No need | R34: Re-use the laptop of ngoc.voleminh
A35: 34 | B35: 22VN00000004 | C35: mong.nguyenthithuy@mapactive.vn | D35: Nguyễn Thị Thúy Mộng | E35: Nguyen Thi Thuy Mong | G35: Merchandise | H35: Senior Brand Marketing Manager | I35: E3 | J35: VN | K35: Office | L35: 45026 | M35: Done | N35: Done | O35: 5430 | R35: Foot Locker
A36: 35 | B36: 22VN00000070 | C36: qui.nguyenthi@mapactive.vn | D36: Nguyễn Thị Quí | E36: Nguyen Thi Qui | G36: Accounting | H36: General Accountant UFO | I36: E3 | J36: VN | K36: Office | L36: 45054 | M36: Done | N36: No need | O36: No need | R36: Re-use Nguyễn Trí Độ' Laptop
A37: 36 | B37: 22VN00000072 | C37: le.daothihong@mapactive.vn | D37: Đào Thị Hồng Lê | E37: Dao Thi Hong Le | G37: Training | H37: Training Assistant Manager | I37: E3 | J37: VN | K37: Office | L37: 45069 | M37: Done | N37: done | O37: 5430
A38: 37 | B38: 22VN00000042 | C38: dien.tranduy@mapactive.vn | D38: Trần Duy Điền | E38: Tran Duy Dien | G38: COE Department | H38: Inventory Control | I38: E3 | J38: VN | K38: Office | L38: 45078 | M38: Done | N38: No need | O38: 3520
A39: 38 | B39: 22VN00000080 | C39: thu.nguyenthanhanh@mapactive.vn | D39: Nguyễn Thanh Anh Thư | E39: Nguyen Thanh Anh Thu | G39: Marketing Department | H39: Visual Merchandise Manager | I39: E3 | J39: VN | K39: Office | L39: 45083 | M39: Done | N39: Done | O39: 5430
A40: 39 | B40: 22VN00000081 | C40: Huy.daoduc@mapactive.vn | D40: Đào Đức Huy | E40: Dao Duc Huy | G40: Operations Department | H40: Area Manager (South) | I40: E3 | J40: VN | K40: Office | L40: 45110 | M40: Done | N40: Done | O40: 5430
A41: 40 | B41: 22VN00000023 | C41: du.nguyenbao@mapactive.vn | D41: Nguyễn Bảo Du | E41: Nguyen Bao Du | G41: HR Department | H41: HR Internship | I41: None | J41: VN | K41: Office | L41: 45139 | M41: No need | N41: Done | O41: Mini PC
A42: 41 | B42: 22VN00000079 | C42: duyen.lethanh@mapactive.vn | D42: Lê Thanh Duyên | E42: Le Thanh Duyen | G42: Marketing Department | H42: Graphic Designer (Foot Locker) | I42: E3 | J42: VN | K42: Office | L42: 45146 | M42: Done | N42: No need | R42: Re-use Vũ Xuân Sơn
A43: 42 | B43: 22VN00000104 | C43: ngoc.nguyenduyen@mapactive.vn | D43: Nguyễn Duyên Ngọc | E43: Nguyen Duyen Ngoc | G43: Business Development | H43: Business Development Manager | I43: E3 | J43: VN | K43: Office | L43: 45174 | M43: Done | N43: No need | O43: 5430 | P43: Done | Q43: Done | R43: Thay anh Hiếu BD (hieu.trantrung)last day ngày 31/08 dùng lại laptop | S43: Business Development Manager
A44: 43 | B44: 22VN00000028 | C44: van.nghiemthihong@mapactive.vn | D44: Nghiêm Thị Hồng Vân | E44: Nghiem Thi Hong Van | G44: Brand Department | H44: Senior Merchandise | I44: E3 | J44: VN | K44: Office | L44: 45214
A45: 44 | B45: 22VN00000052 | C45: xuan.vothihoanganh@mapactive.vn | D45: Võ Thị Hoàng Ánh Xuân | E45: Vo Thi Hoang Anh Xuan | G45: Operations | H45: Operations Executive | I45: E3 | J45: VN | K45: Office | L45: 45218 | M45: None | N45: No need | O45: 7490 | R45: Dùng lại máy ĐẶNG QUỐC TRÍ (OP)
A46: 45 | B46: 22VN00000039 | C46: tram.lengocbich@mapactive.vn | D46: Lê Ngọc BÍch Trâm | E46: Le Ngoc Bich Tram | G46: Marketing Department (Foot Locker) | H46: Marketing Supervisor (Foot Locker) | I46: E3 | J46: VN | K46: Office | L46: 45219 | M46: Done | N46: No need | O46: x280 | Q46: Done | R46: Replace Phạm Thị Mỹ Dung
A47: 46 | B47: 22VN00000051 | C47: mai.nguyenthihuynh@mapactive.vn | D47: Nguyễn Thị Huỳnh Mai | E47: Nguyen Thi Huynh Mai | F47: Maya | H47: Finance, Tax & Accounting Manager | I47: E3 | J47: VN | K47: Office | Q47: Done | R47: laptop cũ của Huỳnh Ngọc Sơn (team Project)
...

Sheet Office_Resigned
A1: Disable Email | B1: No. | C1: Assigned Asset | D1: Email Address | E1: Full Name | F1: Display Name | G1: English Name | H1: Department | I1: JOB TITLE | J1: O365 license | K1: Country | L1: Type | M1: Onboarding Date (dd/mm/yy) | N1: Request email | O1: Purchasing Request | P1: Laptop model | Q1: Laptop delivery | R1: Handover to user | S1: Notes | T1: MAP Level
A3: Request ITSD, IT Server Operation on 23 Feb 2023 (Ticket : WO0000000107284) | B3: 1 | D3: alun.hughes@mapactive.vn | F3: Alun Hughes | J3: Exchange Online Kiosk
A4: Need to check with anh Nhân Log | B4: =B3+1 -> 2 | D4: loan.lethikim@mapactive.vn | I4: Shipping Executive | J4: E3 | M4: 15/02/2023 | N4: Done | P4: 3520 | Q4: Done | R4: Done | S4: đã nghỉ việc
A5: Done | B5: =B4+1 -> 3 | D5: ngoc.voleminh@mapactive.vn | I5: Logistics Manager | J5: E3 | S5: đã nghỉ việc | T5: Manager
A6: Done | B6: =B5+1 -> 4 | D6: trung.lehominh@mapactive.vn | E6: Lê Hồ Minh Trung | F6: Le Ho Minh Trung | H6: Digital | I6: Digital Commercial Senior Manager | J6: E3 | K6: VN | M6: 03/04/2023 | N6: Done | O6: Done | P6: 5430 | S6: đã nghỉ việc
A7: Done | B7: =B6+1 -> 5 | D7: tram.nguyhuynhmai@mapactive.vn | E7: Ngụy Huỳnh Mai Trâm | F7: Nguy Huynh Mai Tram | H7: Logistic | I7: Logistic Admin | J7: E3 | K7: VN | M7: 14/04/2023 | S7: đã nghỉ việc | T7: Associate
A8: Done | B8: =B7+1 -> 6 | D8: nhung.nguyenhong@mapactive.vn | E8: Nguyễn Hồng Nhung | F8: Nguyen Hong Nhung | H8: Training | I8: Training Assistant Manager | J8: E3 | K8: VN | M8: 14/04/2023 | S8: đã nghỉ việc | T8: Associate Manager
A9: Done | B9: =B8+1 -> 7 | D9: ha.dangthivan@mapactive.vn | E9: Đặng Thị Vân Hà | F9: Dang Thi Van Ha | H9: Merchandise | I9: Merchandise | K9: VN | M9: 14/04/2023 | S9: đã nghỉ việc
A10: Done | B10: =B9+1 -> 8 | D10: hau.lenguyentrung@mapactive.vn | E10: Lê Nguyễn Trung Hậu | F10: Le Nguyen Trung Hau | H10: Merchandise | I10: Visual Merchandise Supervisor | K10: VN | M10: 17/04/2023 | N10: Done | O10: Done | P10: 5430 (swap for Henry) | S10: đã nghỉ việc
A11: Done | B11: =B10+1 -> 9 | D11: do.nguyentri@mapactive.vn | E11: Nguyễn Trí Độ | F11: Nguyen Tri Do | H11: Accounting | I11: General Accounting | J11: E3 | K11: VN | M11: 03/04/2023 | N11: Done | O11: Done | P11: 5430 | S11: đã nghỉ việc
A12: Done | B12: =B11+1 -> 10 | D12: nghia.letrong@mapactive.vn | E12: Lê Trọng Nghĩa | F12: Le Trong Nghia | H12: Training | I12: Training Assistant Manager | K12: VN | M12: 24/04/2023 | N12: Done | O12: Done | P12: Re use Laptop Chị Nhung | Q12: Re use Laptop Chị Nhung | S12: đã nghỉ việc
A13: Done | B13: =B12+1 -> 11 | D13: duong.nguyenthihai@mapactive.vn | I13: Internal Audit & Business Process Assistant Manager | J13: E3 | K13: VN | M13: 01/03/2023 | N13: Done | O13: Done | P13: 5430 | Q13: Done | R13: Done | S13: đã nghỉ việc
A14: Done | B14: =B13+1 -> 12 | D14: thuy.dangtranthu@mapactive.vn | I14: Marketing Executive | J14: E3 | K14: VN | M14: 14/07/2023 | N14: Done | O14: Done | P14: 3520 | S14: Disable email after 09/2023 | T14: Executive
A15: Done | B15: =B14+1 -> 13 | D15: son.vuxuan@mapactive.vn | E15: Vũ Xuân Sơn | F15: Vu Xuan Son | H15: Marketing Department | I15: Graphic Designer (Foot Locker) | K15: vn | M15: 15/06/2023 | N15: Done | O15: Done | S15: đã nghỉ việc
A16: Need to keep until end of Oct-2023 | B16: =B15+1 -> 14 | D16: giang.nguyenthiquynh@map.co.id | I16: Merchandiser | J16: E3 | K16: VN | S16: đã nghỉ việc | T16: Senior Executive
A17: Done | B17: =B16+1 -> 15 | D17: hieu.trantrung@mapactive.vn | I17: Business Development Manager | J17: E3 | K17: VN | S17: đã nghỉ việc | T17: Manager
A18: Need to keep until Ms Uyên Confirm | B18: =B17+1 -> 16 | D18: tri.dangquoc@mapactive.vn | I18: Retail Operations Manager | J18: E3 | K18: VN | S18: đã nghỉ việc | T18: Manager
A19: Can revoke license | B19: =B18+1 -> 17 | D19: hoang.phanbao@mapactive.vn | E19: Phan Bảo Hoàng | F19: Phan Bao Hoang | I19: Area Manager (South) | J19: E3 | K19: VN | S19: đã nghỉ việc | T19: Associate Manager
A20: Done | B20: =B19+1 -> 18 | D20: quynh.tranthilam@mapactive.vn | E20: Tran Thi Lâm Quỳnh | F20: Tran Thi lam Quynh | I20: Senior Merchandise | J20: E3 | K20: VN | S20: đã nghỉ việc | T20: Associate Manager
A21: Done | B21: =B20+1 -> 19 | D21: huong.tranquocthien@mapactive.vn | F21: Tran Quoc Thien Huong | I21: Senior Merchandise Planning Manager | J21: E3 | K21: VN | T21: Senior Manager
A22: Need to keep until Kelvin confirm (Oct-2023) | B22: =B21+1 -> 20 | D22: tien.phanthithuy@mapactive.vn | E22: Phan Thị Thủy Tiên | F22: Phan Thi Thuy Tiên | H22: Marketing | I22: Marketing officer | J22: E3 | K22: VN | M22: 8/5/2023 | N22: Done | O22: No need | P22: No need | S22: re-use Le Nguyen Trung Hau's Laptop
A23: done | B23: =B22+1 -> 21 | D23: vothea.iem@map.co.id | E23: Iem Vothea | F23: Iem Vothea | H23: Accounting | I23: Assistant Accountant Manager | J23: E3 | K23: KH | N23: Done | Q23: Done
A24: done | B24: =B23+1 -> 22 | D24: khoa.trandanganh@mapactive.vn | F24: Tran Dang Anh Khoa | I24: COE Officer | J24: E3 | K24: VN | T24: Associate
B25: 1 | D25: dung.phamthimy@mapactive.vn | E25: Phạm Thị Mỹ Dung | F25: Pham Thi My Dung | H25: Marketing Department | I25: Marketing Supervisor | J25: E3 | K25: VN | L25: `` | M25: 23/06/2023 | N25: Done | O25: Done | P25: 3520
A26: Done | B26: 2 | D26: ngan.huynhthibich@mpactive.vn | E26: Huỳnh Thị Bích Ngân | F26: Huynh Thi Bich Ngan | H26: Marketing Department | I26: Marketing Executive | J26: E3 | K26: VN | L26: Office | M26: 45270 | N26: Done | O26: No need | P26: x280 | R26: Done | S26: đã nghỉ việc 13/10/2023
A27: Waiting when HR Complete proccess resign | B27: 3 | C27: 22VN00000085 | D27: hieu.nguyenvutrung@mapactive.vn | E27: Nguyễn Vũ Trung Hiếu | F27: Nguyen Vu Trung Hieu | H27: Marketing Department | I27: Marketing Supervisor | J27: E3 | K27: VN | L27: Office | M27: 45140 | N27: Done | O27: Done | P27: 3520 | Q27: Done | R27: Done
A28: Done | B28: 4 | C28: 22VN00000047 | D28: dang.hohai@mapactive.vn | E28: Hồ Hải Đăng | F28: Ho Hai Dang | I28: Area Manager (South) | J28: E3 | K28: VN | L28: Office
A29: Done | B29: 5 | C29: 22VN00000075 | D29: quynh.phungnhu@mapactive.vn | E29: Phùng Như Quỳnh | F29: Phung Nhu Quynh | I29: Area Manager (North) | J29: E3 | K29: VN | L29: Office
A30: Need to keep until we have replacement | B30: 6 | C30: 22VN00000038 | D30: Trương Hồng Hương | E30: Truong Hong Huong | F30: Jolie | H30: Brand Manager (Birkenstock) | I30: E3 | J30: VN | K30: Office | S30: Senior Manager
A31: Done | B31: 7 | C31: 22VN00000086 | D31: quynh.nguyennhu@mapactive.vn | E31: Nguyễn Như Quỳnh | F31: Nguyen Nhu Quynh | H31: Brand Department | I31: Brand Manager (Bata) | J31: E3 | K31: VN | L31: Office | M31: 45152 | N31: Done | O31: Done | P31: 5430 | S31: BM for Bata, New Era
A32: Done | B32: 22 | C32: 22VN00000029 | D32: Tram.phamthibao@mapactive.vn | E32: Phạm Thị Bảo Trâm | F32: Pham Thi Bao Tram | I32: Marketing officer | J32: E3 | K32: VN | L32: Office | T32: Associate
B33: 11 | C33: 22VN00000026 | D33: dat.tranquoc@mapactive.vn | E33: Trần Quốc Đạt | F33: Tran Quoc Dat | I33: IT Officer | J33: E3 | K33: VN | L33: Office | T33: Senior Associate
A34: Done | C34: 22VN00000049 | D34: phong.phanhoai@mapactive.vn | E34: Phan Hoài Phong | F34: Phan Hoai Phong | H34: Marketing Department | I34: Visual Merchandise Executive | J34: E3 | K34: VN | L34: Office | M34: 45078 | N34: Done | O34: No need | P34: 3520
A35: Done | C35: 22VN00000068 | D35: my.tranthitoan@mapactive.vn | E35: Trần Thị Toàn Mỹ | F35: Tran Thi Toan My | I35: Senior Planning Merchandise | J35: E3 | K35: VN | L35: Office | M35: 45012 | N35: Done | O35: Done | P35: 3520 | Q35: Done | R35: Done
B36: =Office_Resigned!A57+1 -> 19 | C36: 22VN00000052 | D36: tra.truongvantin@mapactive.vn | E36: Trương Văn tín Trà | F36: Truong Van Tin Tra | I36: Project Supervisor | J36: E3 | K36: VN | L36: Office | T36: Senior Executive
B37: 32 | C37: 22VN00000040 | D37: tien.trantrung@mapactive.vn | E37: Trần Trung Tiến | F37: Tran Trung Tien | H37: Merchandise | I37: Senior Merchandise | J37: E3 | K37: VN | L37: Office | M37: 45012 | N37: Done | O37: No need | P37: 3520 | Q37: No need | R37: Done | S37: Replace Diệp team Ms. Jolie will resign on 10/04. Provide temporary MiniPC to use
B38: =Office_Resigned!A64+1 -> 20 | C38: 22VN00000009 | D38: hoa.mailecam@mapactive.vn | E38: Mai Lê Cẩm Hòa | F38: Mai Le Cam Hoa | G38: Mia | I38: Retail Admin Executive | J38: E3 | K38: VN | L38: Office | T38: Senior Executive
B39: =Office_Resigned!B45+1 -> #VALUE! | C39: 22VN00000094 | D39: minh.letranthien@mapactive.vn | E39: Lê Trần Thiên Minh | F39: Le Tran Thien Minh | H39: Operations Department | I39: Retail Operations Division Manager | J39: E3 | K39: VN | L39: Office | M39: 45136 | N39: Done | O39: Done | P39: 5430
B40: =VN_Emails!A27+1 -> 27 | C40: 22VN00000039 | D40: linh.thainhat@mapactive.vn | E40: Thái Nhật Linh | F40: Thai Nhat Linh | I40: Merchandiser | J40: E3 | K40: VN | L40: Office | T40: Senior Executive
B41: =Office_Resigned!A48+1 -> 21 | C41: 22VN00000062 | D41: loan.nguyenhoang@mapactive.vn | E41: Nguyễn Hoàng Loan | F41: Nguyen Hoang Loan | I41: Project Supervisor | J41: E3 | K41: VN | L41: Office | M41: 44984 | N41: Done | O41: Done | P41: 3520 | Q41: Done | R41: Done
...
